<?xml version="1.0"?>
<robot name="pendulum">

  <link name="base">
    <visual>
      <geometry>
        <box size="0.2 0.2 0.2"/>
      </geometry>
      <origin xyz="0 0 0"/>
      <material name="blue">
        <color rgba="0 0 .8 1"/>
      </material>
    </visual>
    <inertial>
      <mass value="0"/>
      <inertia ixx="1.0" ixy="0.0" ixz="0.0" iyy="1.0" iyz="0.0" izz="1.0"/>
    </inertial>
  </link>

  <link name="pole">
    <visual>
      <geometry>
        <box size="0.15 0.15 1.0"/>	
      </geometry>
      <origin rpy="0 0 0" xyz="0 0 -0.5"/>
      <material name="white">
        <color rgba="1 1 1 1"/>
      </material>
    </visual>
    <inertial>
    <origin xyz="0 0 0.5"/>
      <mass value="0.1"/>
      <inertia ixx="1.0" ixy="0.0" ixz="0.0" iyy="1.0" iyz="0.0" izz="1.0"/>
    </inertial>
  </link>

  <joint name="base_to_pole" type="prismatic">
    <axis xyz="0 1 0"/>
    <origin xyz="0.0 0.0 0"/>
    <parent link="base"/>
    <child link="pole"/>
    <dynamics damping=".025"/>
    <limit effort="1000.0" lower="-100" upper="100" velocity="100"/>
  </joint>

</robot>
